<mujoco model="go2 feet only">
  <compiler angle="radian" meshdir="../../../../../mujoco_menagerie/unitree_go2/assets" autolimits="true"/>

  <option iterations="1" ls_iterations="5" timestep="0.004" integrator="Euler">
    <flag eulerdamp="disable"/>
  </option>

  <default>
    <default class="go2">
      <!-- This globaly disables all collisions. -->
      <geom condim="1" contype="0" conaffinity="0"/>
      <joint axis="0 1 0" armature="0.01" damping="2.0"/>
      <general forcerange="-24 24" biastype="affine" gainprm="50 0 0" biasprm="0 -50 -0.5"/>
      <!-- <position forcerange="-24.0 24.0" inheritrange="1" kp="60"/> -->

      <default class="abduction">
        <joint axis="1 0 0" range="-1.0472 1.0472" frictionloss="0.3"/>
        <general ctrlrange="-0.9472 0.9472"/>
      </default>
      
      <default class="hip">
        <joint range="-1.5708 3.4907" frictionloss="0.3"/>
        <general ctrlrange="-1.4 2.5"/>
      </default>

      <default class="knee">
        <joint range="-2.7227 -0.83776" frictionloss="1.0"/>
        <!-- <position forcerange="-35.55 35.55"/> -->
        <general ctrlrange="-2.6227 -0.84776"/>
      </default>

      <default class="visual">
        <geom type="mesh" contype="0" conaffinity="0" group="2" material="dark"/>
      </default>
      
      <default class="collision">
        <geom group="3" type="capsule"/>
        <default class="hip_left1">
          <geom size="0.046 0.02" pos="0 0.045 0" quat="1 1 0 0" type="cylinder"/>
        </default>
        <default class="hip_left2">
          <geom size="0.031 0.02" pos="0 0.065 0" quat="1 1 0 0" type="cylinder"/>
        </default>
        <default class="hip_left3">
          <geom size="0.046 0.02" quat="1 1 0 0" type="cylinder"/>
        </default>
        <default class="hip_right1">
          <geom size="0.046 0.02" pos="0 -0.045 0" quat="1 1 0 0" type="cylinder"/>
        </default>
        <default class="hip_right2">
          <geom size="0.031 0.02" pos="0 -0.065 0" quat="1 1 0 0" type="cylinder"/>
        </default>
        <default class="hip_right3">
          <geom size="0.046 0.02" quat="1 1 0 0" type="cylinder"/>
        </default>
        <default class="thigh1">
          <geom size="0.015" fromto="-0.02 0 0 -0.02 0 -0.16"/>
        </default>
        <default class="thigh2">
          <geom size="0.015" fromto="0 0 0 -0.02 0 -0.1"/>
        </default>
        <default class="thigh3">
          <geom size="0.015" fromto="-0.02 0 -0.16 0 0 -0.2"/>
        </default>
        <default class="calf1">
          <geom size="0.01" fromto="0 0 0 0.02 0 -0.13"/>
        </default>
        <default class="calf2">
          <geom size="0.01" fromto="0.02 0 -0.13 0 0 -0.2"/>
        </default>
        <default class="foot">
          <!--
          This specific line enables collisions for the feet only.
          The floor is contype=1, conaffinity=0 so this implies that the feet cannot
          collide with each other, but they can collide with the floor.
          -->
          <geom type="sphere" size="0.023" pos="0 0 -0.213" solimp="0.9 .95 0.023" contype="0" conaffinity="1"/>
        </default>
      </default>
    </default>
  </default>

  <!-- <asset>
    <material name="dark" rgba="0.2 0.2 0.2 1"/>
    <mesh class="go2" file="../../../../mujoco_menagerie/unitree_go2/assets/trunk.stl"/>
    <mesh class="go2" file="../../../../mujoco_menagerie/unitree_go2/assets/hip.stl"/>
    <mesh class="go2" file="../../../../mujoco_menagerie/unitree_go2/assets/thigh_mirror.stl"/>
    <mesh class="go2" file="../../../../mujoco_menagerie/unitree_go2/assets/calf.stl"/>
    <mesh class="go2" file="../../../../mujoco_menagerie/unitree_go2/assets/thigh.stl"/>
  </asset> -->

  <asset>
    <material name="metal" rgba=".9 .95 .95 1"/>
    <material name="black" rgba="0 0 0 1"/>
    <material name="white" rgba="1 1 1 1"/>
    <material name="gray" rgba="0.671705 0.692426 0.774270 1"/>

    <mesh class="go2" file="../../../../mujoco_menagerie/unitree_go2/assets/base_0.obj"/>
    <mesh class="go2" file="../../../../mujoco_menagerie/unitree_go2/assets/base_1.obj"/>
    <mesh class="go2" file="../../../../mujoco_menagerie/unitree_go2/assets/base_2.obj"/>
    <mesh class="go2" file="../../../../mujoco_menagerie/unitree_go2/assets/base_3.obj"/>
    <mesh class="go2" file="../../../../mujoco_menagerie/unitree_go2/assets/base_4.obj"/>
    <mesh class="go2" file="../../../../mujoco_menagerie/unitree_go2/assets/hip_0.obj"/>
    <mesh class="go2" file="../../../../mujoco_menagerie/unitree_go2/assets/hip_1.obj"/>
    <mesh class="go2" file="../../../../mujoco_menagerie/unitree_go2/assets/thigh_0.obj"/>
    <mesh class="go2" file="../../../../mujoco_menagerie/unitree_go2/assets/thigh_1.obj"/>
    <mesh class="go2" file="../../../../mujoco_menagerie/unitree_go2/assets/thigh_mirror_0.obj"/>
    <mesh class="go2" file="../../../../mujoco_menagerie/unitree_go2/assets/thigh_mirror_1.obj"/>
    <mesh class="go2" file="../../../../mujoco_menagerie/unitree_go2/assets/calf_0.obj"/>
    <mesh class="go2" file="../../../../mujoco_menagerie/unitree_go2/assets/calf_1.obj"/>
    <mesh class="go2" file="../../../../mujoco_menagerie/unitree_go2/assets/calf_mirror_0.obj"/>
    <mesh class="go2" file="../../../../mujoco_menagerie/unitree_go2/assets/calf_mirror_1.obj"/>
    <mesh class="go2" file="../../../../mujoco_menagerie/unitree_go2/assets/foot.obj"/>
  </asset>

  <worldbody>
    <light name="spotlight" mode="targetbodycom" target="trunk" pos="3 0 4"/>
    <body name="trunk" pos="0 0 0.445" childclass="go1">
      
      <camera name="track" pos="0.846 -1.3 0.316" xyaxes="0.866 0.500 0.000 -0.171 0.296 0.940" mode="trackcom"/>
      <camera name="top" pos="-1 0 1" xyaxes="0 -1 0 0.7 0 0.7" mode="trackcom"/>
      <camera name="side" pos="0 -1 .3" xyaxes="1 0 0 0 1 2" mode="trackcom"/>
      <camera name="back" pos="-1 0 .3" xyaxes="0 -1 0 1 0 2" mode="trackcom"/>
      
      <site name="head" pos="0.3 0 0" rgba="1 0 0 1" size="0.02" group="5"/>
      
      <inertial pos="0.021112 0 -0.005366" quat="-0.000543471 0.713435 -0.00173769 0.700719" mass="6.921"
        diaginertia="0.107027 0.0980771 0.0244531"/>
      <freejoint/>
      <!-- <geom class="visual" mesh="trunk"/> -->
      <geom mesh="base_0" material="black" class="visual"/>
      <geom mesh="base_1" material="black" class="visual"/>
      <geom mesh="base_2" material="black" class="visual"/>
      <geom mesh="base_3" material="white" class="visual"/>
      <geom mesh="base_4" material="gray" class="visual"/>

      <geom class="collision" size="0.057 0.04675 0.057" type="box"/>
      <geom class="collision" size="0.05 0.045" pos="0.285 0 0.01"/>
      <geom class="collision" size="0.047" pos="0.293 0 -0.06"/>
      <!-- <geom class="collision" quat="1 0 1 0" pos="0 -0.04 0" size="0.058 0.125" type="cylinder"/>
      <geom class="collision" quat="1 0 1 0" pos="0 +0.04 0" size="0.058 0.125" type="cylinder"/> -->
      <site name="imu" pos="-0.02557 0 0.04232" group="5"/>

      <body name="FR_hip" pos="0.1934 -0.0465 0">
        <inertial pos="-0.0054 -0.00194 -0.000105" quat="0.507341 0.514169 0.495027 0.482891" mass="0.68"
          diaginertia="0.000734064 0.000468438 0.000398719"/>
        <joint class="abduction" name="FR_hip_joint"/>
        <geom class="visual" mesh="hip" quat="1 0 0 0"/>
        <geom class="hip_right1"/>
        <geom class="hip_right2"/>
        <body name="FR_thigh" pos="0 -0.08 0">
          <inertial pos="-0.00304722 0.019315 -0.0305004" quat="0.498237 0.505462 0.499245 0.497014" mass="0.678"
            diaginertia="0.00088403 0.000596003 0.000479967"/>
          <joint class="hip" name="FR_thigh_joint"/>
          <!-- <geom class="visual" mesh="thigh_mirror"/> -->
          <geom class="thigh1"/>
          <geom class="thigh2"/>
          <geom class="thigh3"/>
          <geom mesh="hip_0" material="metal" class="visual" quat="4.63268e-05 1 0 0"/>
          <geom mesh="hip_1" material="gray" class="visual" quat="4.63268e-05 1 0 0"/>

          <body name="FR_calf" pos="0 0 -0.213">
            <inertial pos="0.00629595 0.000622121 -0.141417" quat="0.703508 -0.00450087 0.00154099 0.710672"
              mass="0.241352" diaginertia="0.0014901 0.00146356 5.31397e-05"/>
            <joint class="knee" name="FR_calf_joint"/>
            <!-- <geom class="visual" mesh="calf"/> -->
            <geom mesh="calf_mirror_0" material="gray" class="visual"/>
            <geom mesh="calf_mirror_1" material="black" class="visual"/>
            <geom class="calf1"/>
            <geom class="calf2"/>

            <geom pos="0 0 -0.213" mesh="foot" class="visual" material="black"/>
            <geom name="FR" class="foot"/>
            <site name="FR" pos="0 0 -0.213" type="sphere" size="0.023" group="5"/>

          </body>
        </body>
      </body>
      <body name="FL_hip" pos="0.1934 0.0465 0">
        <inertial pos="--0.0054 0.00194 -0.000105" quat="0.497014 0.499245 0.505462 0.498237" mass="0.678"
          diaginertia="0.00088403 0.000596003 0.000479967"/>
        <joint class="abduction" name="FL_hip_joint"/>
        <!-- <geom class="visual" mesh="hip"/> -->
        <geom mesh="hip_0" material="metal" class="visual"/>
        <geom mesh="hip_1" material="gray" class="visual"/>
        <geom class="hip_left1"/>
        <geom class="hip_left2"/>

        <body name="FL_thigh" pos="0 0.0955 0">
          <inertial pos="-0.00374 -0.0223 -0.0327" quat="0.829533 0.0847635 -0.0200632 0.551623" mass="1.152"
            diaginertia="0.00594973 0.00584149 0.000878787"/>
          <joint class="hip" name="FL_thigh_joint"/>
          <!-- <geom class="visual" mesh="thigh"/> -->
          <geom mesh="thigh_0" material="metal" class="visual"/>
          <geom mesh="thigh_1" material="gray" class="visual"/>
          <geom class="thigh1"/>
          <geom class="thigh2"/>
          <geom class="thigh3"/>

          <body name="FL_calf" pos="0 0 -0.213">
            <inertial pos="0.00629595 -0.000622121 -0.141417" quat="0.710672 0.00154099 -0.00450087 0.703508"
              mass="0.241352" diaginertia="0.0014901 0.00146356 5.31397e-05"/>
            <joint class="knee" name="FL_calf_joint"/>
            <!-- <geom class="visual" mesh="calf"/> -->
            <geom mesh="calf_0" material="gray" class="visual"/>
            <geom mesh="calf_1" material="black" class="visual"/>
            <geom class="calf1"/>
            <geom class="calf2"/>
            <geom name="FL" class="foot"/>
            <site name="FL" pos="0 0 -0.213" type="sphere" size="0.023" group="5"/>
          </body>
          
        </body>
      </body>
      <body name="RR_hip" pos="-0.1934 -0.0465 0">
        <inertial pos="0.0054 -0.00194 -0.000105" quat="0.499245 0.497014 0.498237 0.505462" mass="0.678"
          diaginertia="0.00088403 0.000596003 0.000479967"/>
        
        <joint class="abduction" name="RR_hip_joint"/>
        <!-- <geom class="visual" quat="0 0 0 -1" mesh="hip"/> -->
        <geom mesh="hip_0" material="metal" class="visual" quat="2.14617e-09 4.63268e-05 4.63268e-05 -1"/>
        <geom mesh="hip_1" material="gray" class="visual" quat="2.14617e-09 4.63268e-05 4.63268e-05 -1"/>
        <geom class="hip_right1"/>
        <geom class="hip_right2"/>
        <geom class="hip_right3"/>

        <body name="RR_thigh" pos="0 -0.0955 0">
          <inertial pos="-0.00374 0.0223 -0.0327" quat="0.551623 -0.0200632 0.0847635 0.829533" mass="1.152"
            diaginertia="0.00594973 0.00584149 0.000878787"/>
          <joint class="hip" name="RR_thigh_joint"/>
          <!-- <geom class="visual" mesh="thigh_mirror"/> -->
          <geom mesh="thigh_mirror_0" material="metal" class="visual"/>
          <geom mesh="thigh_mirror_1" material="gray" class="visual"/>
          <geom class="thigh1"/>
          <geom class="thigh2"/>
          <geom class="thigh3"/>

          <body name="RR_calf" pos="0 0 -0.213">
            <inertial pos="0.00629595 0.000622121 -0.141417" quat="0.703508 -0.00450087 0.00154099 0.710672"
              mass="0.241352" diaginertia="0.0014901 0.00146356 5.31397e-05"/>

            <joint class="knee" name="RR_calf_joint"/>
            <!-- <geom class="visual" mesh="calf"/> -->
            <geom mesh="calf_mirror_0" material="gray" class="visual"/>
            <geom mesh="calf_mirror_1" material="black" class="visual"/>
            <geom class="calf1"/>
            <geom class="calf2"/>
            <geom name="RR" class="foot"/>
            <site name="RR" pos="0 0 -0.213" type="sphere" size="0.023" group="5"/>
          </body>

        </body>
      </body>
      <body name="RL_hip" pos="-0.1934 0.0465 0">
        <inertial pos="0.0054 0.00194 -0.000105" quat="0.505462 0.498237 0.497014 0.499245" mass="0.678"
          diaginertia="0.00088403 0.000596003 0.000479967"/>     
        <joint class="abduction" name="RL_hip_joint"/>
        <!-- <geom class="visual" quat="0 0 1 0" mesh="hip"/> -->
        <geom mesh="hip_0" material="metal" class="visual" quat="4.63268e-05 0 1 0"/>
        <geom mesh="hip_1" material="gray" class="visual" quat="4.63268e-05 0 1 0"/>
        <geom class="hip_left1"/>
        <geom class="hip_left2"/>
        <geom class="hip_left3"/>

        <body name="RL_thigh" pos="0 0.0955 0">
          <inertial pos="-0.00374 -0.0223 -0.0327" quat="0.829533 0.0847635 -0.0200632 0.551623" mass="1.152"
            diaginertia="0.00594973 0.00584149 0.000878787"/>
          <joint class="hip" name="RL_thigh_joint"/>
          <!-- <geom class="visual" mesh="thigh"/> -->
          <geom mesh="thigh_0" material="metal" class="visual"/>
          <geom mesh="thigh_1" material="gray" class="visual"/>
          <geom class="thigh1"/>
          <geom class="thigh2"/>
          <geom class="thigh3"/>

          <body name="RL_calf" pos="0 0 -0.213">
            <inertial pos="0.00629595 -0.000622121 -0.141417" quat="0.710672 0.00154099 -0.00450087 0.703508"
              mass="0.241352" diaginertia="0.0014901 0.00146356 5.31397e-05"/>
            <joint class="knee" name="RL_calf_joint"/>
            <!-- <geom class="visual" mesh="calf"/> -->
            <geom mesh="calf_0" material="gray" class="visual"/>
            <geom mesh="calf_1" material="black" class="visual"/>
            <geom class="calf1"/>
            <geom class="calf2"/>

            <geom name="RL" class="foot"/>
            <site name="RL" pos="0 0 -0.213" type="sphere" size="0.023" group="5"/>
          </body>
        </body>
      </body>
    </body>
  </worldbody>


<!-- si control es por posicion -->
  <!-- <actuator>
    <position class="abduction" name="FR_hip" joint="FR_hip_joint"/>
    <position class="hip" name="FR_thigh" joint="FR_thigh_joint"/>
    <position class="knee" name="FR_calf" joint="FR_calf_joint"/>
    <position class="abduction" name="FL_hip" joint="FL_hip_joint"/>
    <position class="hip" name="FL_thigh" joint="FL_thigh_joint"/>
    <position class="knee" name="FL_calf" joint="FL_calf_joint"/>
    <position class="abduction" name="RR_hip" joint="RR_hip_joint"/>
    <position class="hip" name="RR_thigh" joint="RR_thigh_joint"/>
    <position class="knee" name="RR_calf" joint="RR_calf_joint"/>
    <position class="abduction" name="RL_hip" joint="RL_hip_joint"/>
    <position class="hip" name="RL_thigh" joint="RL_thigh_joint"/>
    <position class="knee" name="RL_calf" joint="RL_calf_joint"/>
  </actuator> -->


<!-- original es por torque: -->
  <actuator>
    <general class="abduction" name="FL_hip" joint="FL_hip_joint"/>
    <general class="hip" name="FL_thigh" joint="FL_thigh_joint"/>
    <general class="knee" name="FL_calf" joint="FL_calf_joint"/>
    <general class="abduction" name="FR_hip" joint="FR_hip_joint"/>
    <general class="hip" name="FR_thigh" joint="FR_thigh_joint"/>
    <general class="knee" name="FR_calf" joint="FR_calf_joint"/>
    <general class="abduction" name="RL_hip" joint="RL_hip_joint"/>
    <general class="hip" name="RL_thigh" joint="RL_thigh_joint"/>
    <general class="knee" name="RL_calf" joint="RL_calf_joint"/>
    <general class="abduction" name="RR_hip" joint="RR_hip_joint"/>
    <general class="hip" name="RR_thigh" joint="RR_thigh_joint"/>
    <general class="knee" name="RR_calf" joint="RR_calf_joint"/>
  </actuator>

    <sensor>
    <jointpos joint="FL_hip_joint" name="abduction_front_left_pos"/>
    <jointpos joint="FL_thigh_joint" name="hip_front_left_pos"/>
    <jointpos joint="FL_calf_joint" name="knee_front_left_pos"/>
    <jointpos joint="RL_hip_joint" name="abduction_hind_left_pos"/>
    <jointpos joint="RL_thigh_joint" name="hip_hind_left_pos"/>
    <jointpos joint="RL_calf_joint" name="knee_hind_left_pos"/>
    <jointpos joint="FR_hip_joint" name="abduction_front_right_pos"/>
    <jointpos joint="FR_thigh_joint" name="hip_front_right_pos"/>
    <jointpos joint="FR_calf_joint" name="knee_front_right_pos"/>
    <jointpos joint="RR_hip_joint" name="abduction_hind_right_pos"/>
    <jointpos joint="RR_thigh_joint" name="hip_hind_right_pos"/>
    <jointpos joint="RR_calf_joint" name="knee_hind_right_pos"/>
    <jointvel joint="FL_hip_joint" name="abduction_front_left_vel"/>
    <jointvel joint="FL_thigh_joint" name="hip_front_left_vel"/>
    <jointvel joint="FL_calf_joint" name="knee_front_left_vel"/>
    <jointvel joint="RL_hip_joint" name="abduction_hind_left_vel"/>
    <jointvel joint="RL_thigh_joint" name="hip_hind_left_vel"/>
    <jointvel joint="RL_calf_joint" name="knee_hind_left_vel"/>
    <jointvel joint="FR_hip_joint" name="abduction_front_right_vel"/>
    <jointvel joint="FR_thigh_joint" name="hip_front_right_vel"/>
    <jointvel joint="FR_calf_joint" name="knee_front_right_vel"/>
    <jointvel joint="RR_hip_joint" name="abduction_hind_right_vel"/>
    <jointvel joint="RR_thigh_joint" name="hip_hind_right_vel"/>
    <jointvel joint="RR_calf_joint" name="knee_hind_right_vel"/>
    <framezaxis objtype="site" objname="imu" name="upvector"/>
    <gyro site="imu" name="gyro"/>
    <accelerometer site="imu" name="accelerometer"/>
    <framequat objtype="site" objname="imu" name="orientation"/>
    <framepos objtype="site" objname="imu" name="global_position"/>
    <framelinvel objtype="site" objname="imu" name="global_linvel"/>
    <frameangvel objtype="site" objname="imu" name="global_angvel"/>
    <velocimeter site="imu" name="local_linvel"/>
  </sensor>


</mujoco>
